<?xml version='1.0' encoding='utf-8'?>
<mujoco model="dusan">
  <worldbody>
    <geom type="plane" size="1 1 .1" rgba=".8 .8 .8 1" />
    <light diffuse=".8 .8 .8" pos="0 0 3" dir="0 0 -1" />
    <body name="thorax" pos="0 0 1.643728813559322" euler="90 0 0">
      <joint type="free" pos="0 0 0" />
      <geom type="capsule" size="0.12265536723163843 0.10447740112994347" pos="0 -0.12265536723163843 0" euler="0 0 0" rgba="0.2 0.4 0.8 1" />
      <geom type="capsule" size="0.12265536723163843 0.10447740112994347" pos="0 -0.3679661016949153 0" euler="0 0 0" rgba="0.2 0.4 0.8 1" />
      <inertial mass="30.4" pos="0.0 -0.204221186440678 -0.0014718644067796612" fullinertia="0.02 0.03 0.04 0.001 0.002 0.003" />
      <body name="head" pos="0 0 0">
        <joint name="head_x" type="hinge" axis="1 0 0" pos="0 0 0" range="-45.0 45.0" />
        <joint name="head_y" type="hinge" axis="0 1 0" pos="0 0 0" range="-80 80" />
        <joint name="head_z" type="hinge" axis="0 0 1" pos="0 0 0" range="-60 75.0" />
        <geom type="sphere" size="0.15313559322033898" pos="0 0.15313559322033898 0" euler="0 0 0" rgba="0.2 0.4 0.8 1" />
        <inertial mass="6.7" pos="0.0061254237288135595 0.16354881355932205 0.000306271186440678" fullinertia="0.02 0.03 0.04 0.001 0.002 0.003" />
      </body>
      <body name="abdomen" pos="0 -0.3679661016949153 0">
        <joint name="abdomen_x" type="hinge" axis="1 0 0" pos="0 0 0" range="-12.5 12.5" />
        <joint name="abdomen_y" type="hinge" axis="0 1 0" pos="0 0 0" range="-15 15" />
        <joint name="abdomen_z" type="hinge" axis="0 0 1" pos="0 0 0" range="-25 12.5" />
        <geom type="capsule" size="0.08317796610169491 0.1104449152542373" pos="0 -0.16635593220338982 0" euler="0 0 0" rgba="0.2 0.4 0.8 1" />
        <inertial mass="2.9" pos="0.02927864406779661 -0.06005449152542372 -0.005489745762711864" fullinertia="0.02 0.03 0.04 0.001 0.002 0.003" />
        <body name="pelvis" pos="0 -0.16635593220338982 0">
          <joint name="pelvis_x" type="hinge" axis="1 0 0" pos="0 0 0" range="-12.5 12.5" />
          <joint name="pelvis_y" type="hinge" axis="0 1 0" pos="0 0 0" range="-15 15" />
          <joint name="pelvis_z" type="hinge" axis="0 0 1" pos="0 0 0" range="-25 12.5" />
          <geom type="capsule" size="0.05122881355932203 0.12917372881355935" pos="0 -0.10245762711864406 0" euler="0 0 0" rgba="0.2 0.4 0.8 1" />
          <inertial mass="14.2" pos="-0.00020491525423728814 -0.02889305084745762 -0.0006147457627118644" fullinertia="0.02 0.03 0.04 0.001 0.002 0.003" />
          <body name="left_thigh" pos="0 -0.10245762711864406 -0.15478813559322036">
            <joint name="left_hip_x" type="hinge" axis="1 0 0" pos="0 0 0" range="-20.0 40.0" />
            <joint name="left_hip_y" type="hinge" axis="0 1 0" pos="0 0 0" range="-40 50" />
            <joint name="left_hip_z" type="hinge" axis="0 0 1" pos="0 0 0" range="-30 100.0" />
            <geom type="capsule" size="0.08978813559322034 0.19307203389830507" pos="0 -0.23796610169491525 0" euler="-90 0 0" rgba="0.2 0.4 0.8 1" />
            <inertial mass="12.3" pos="-0.019513220338983048 -0.20417491525423728 0.015705762711864406" fullinertia="0.02 0.03 0.04 0.001 0.002 0.003" />
            <site name="greater_trochanter_left" pos="0.0 0.0 -0.08978813559322034" size="0.02" rgba="1 0 0 1" />
            <site name="lateral_femoral_epicondyle_left" pos="0.0 -0.4759322033898305 -0.08978813559322034" size="0.02" rgba="1 0 0 1" />
            <body name="left_shank" pos="0 -0.4759322033898305 0">
              <joint name="left_knee_z" type="hinge" axis="0 0 1" pos="0 0 0" range="-150 0.0" />
              <geom type="capsule" size="0.056737288135593214 0.21014830508474577" pos="0 -0.23851694915254237 0" euler="-90 0 0" rgba="0.2 0.4 0.8 1" />
              <inertial mass="4.8" pos="-0.022897627118644067 -0.19558389830508474 0.0033392372881355928" fullinertia="0.02 0.03 0.04 0.001 0.002 0.003" />
              <site name="lateral_maleollus_left" pos="0.0 -0.47703389830508475 -0.056737288135593214" size="0.02" rgba="1 0 0 1" />
              <body name="left_foot" pos="0 -0.47703389830508475 0">
                <joint name="left_ankle_y" type="hinge" axis="0 1 0" pos="0 0 0" range="-30 30" />
                <joint name="left_ankle_z" type="hinge" axis="0 0 1" pos="0 0 0" range="-20 30.0" />
                <geom type="capsule" size="0.05563559322033899 0.04875" pos="0.07656779661016949 0 0" euler="0 90 0" rgba="0.2 0.4 0.8 1" />
                <inertial mass="1.2" pos="0.07687406779661017 -0.030473983050847454 0.005206610169491525" fullinertia="0.02 0.03 0.04 0.001 0.002 0.003" />
                <site name="metatarsal_fifth_left" pos="0.11485169491525424 0.0 -0.05563559322033899" size="0.02" rgba="1 0 0 1" />
              </body>
            </body>
          </body>
          <body name="right_thigh" pos="0 -0.10245762711864406 0.15478813559322036">
            <joint name="right_hip_x" type="hinge" axis="1 0 0" pos="0 0 0" range="-40.0 20.0" />
            <joint name="right_hip_y" type="hinge" axis="0 1 0" pos="0 0 0" range="-40 50" />
            <joint name="right_hip_z" type="hinge" axis="0 0 1" pos="0 0 0" range="-30 100.0" />
            <geom type="capsule" size="0.08978813559322034 0.19307203389830507" pos="0 -0.23796610169491525 0" euler="-90 0 0" rgba="0.2 0.4 0.8 1" />
            <inertial mass="12.3" pos="-0.019513220338983048 -0.20417491525423728 0.015705762711864406" fullinertia="0.02 0.03 0.04 0.001 0.002 0.003" />
            <site name="greater_trochanter_right" pos="0.0 0.0 0.08978813559322034" size="0.02" rgba="1 0 0 1" />
            <site name="lateral_femoral_epicondyle_right" pos="0.0 -0.4759322033898305 0.08978813559322034" size="0.02" rgba="1 0 0 1" />
            <body name="right_shank" pos="0 -0.4759322033898305 0">
              <joint name="right_knee_z" type="hinge" axis="0 0 1" pos="0 0 0" range="-150 0.0" />
              <geom type="capsule" size="0.056737288135593214 0.21014830508474577" pos="0 -0.23851694915254237 0" euler="-90 0 0" rgba="0.2 0.4 0.8 1" />
              <inertial mass="4.8" pos="-0.022897627118644067 -0.19558389830508474 0.0033392372881355928" fullinertia="0.02 0.03 0.04 0.001 0.002 0.003" />
              <site name="lateral_maleollus_right" pos="0.0 -0.47703389830508475 0.056737288135593214" size="0.02" rgba="1 0 0 1" />
              <body name="right_foot" pos="0 -0.47703389830508475 0">
                <joint name="right_ankle_y" type="hinge" axis="0 1 0" pos="0 0 0" range="-30 30" />
                <joint name="right_ankle_z" type="hinge" axis="0 0 1" pos="0 0 0" range="-20 30.0" />
                <geom type="capsule" size="0.05563559322033899 0.04875" pos="0.07656779661016949 0 0" euler="0 90 0" rgba="0.2 0.4 0.8 1" />
                <inertial mass="1.2" pos="0.07687406779661017 -0.030473983050847454 0.005206610169491525" fullinertia="0.02 0.03 0.04 0.001 0.002 0.003" />
                <site name="metatarsal_fifth_right" pos="0.11485169491525424 0.0 0.05563559322033899" size="0.02" rgba="1 0 0 1" />
              </body>
            </body>
          </body>
        </body>
      </body>
      <body name="left_upper_arm" pos="0 -0.1011906779661017 -0.2782506779661017">
        <joint name="left_shoulder_x" type="hinge" axis="1 0 0" pos="0 0.04056 0" range="-50.0 180.0" />
        <joint name="left_shoulder_y" type="hinge" axis="0 1 0" pos="0 0.04056 0" range="-90 90" />
        <joint name="left_shoulder_z" type="hinge" axis="0 0 1" pos="0 0.04056 0" range="-50 180.0" />
        <geom type="capsule" size="0.05563559322033899 0.12476694915254237" pos="0 -0.11202474576271186 0" euler="-90 0 0" rgba="0.2 0.4 0.8 1" />
        <inertial mass="2.4" pos="0.005493050847457628 -0.14709169491525426 -0.009460254237288135" fullinertia="0.02 0.03 0.04 0.001 0.002 0.003" />
        <site name="acromion_left" pos="0.0 0.061033898305084745 -0.022254237288135595" size="0.02" rgba="1 0 0 1" />
        <site name="lateral_humeral_epicondyle_left" pos="0.0 -0.3051694915254237 -0.05563559322033899" size="0.02" rgba="1 0 0 1" />
        <body name="left_forearm" pos="0 -0.3051694915254237 0">
          <joint name="left_elbow_z" type="hinge" axis="0 0 1" pos="0 0 0" range="0 150.0" />
          <geom type="capsule" size="0.0473728813559322 0.13220338983050844" pos="0 -0.15588983050847455 0" euler="-90 0 0" rgba="0.2 0.4 0.8 1" />
          <inertial mass="1.7000000000000002" pos="-0.0040531355932203385 -0.13001211864406778 0.00342957627118644" fullinertia="0.02 0.03 0.04 0.001 0.002 0.003" />
          <body name="left_hand" pos="0 -0.3117796610169491 0">
            <joint name="left_wrist_y" type="hinge" axis="0 1 0" pos="0 0 0" range="-80 80" />
            <joint name="left_wrist_z" type="hinge" axis="0 0 1" pos="0 0 0" range="-60 60.0" />
            <geom type="capsule" size="0.04902542372881356 0.019555084745762712" pos="0 -0.04406779661016949 0" euler="-90 0 0" rgba="0.2 0.4 0.8 1" />
            <inertial mass="0.6" pos="0.007227118644067796 -0.07394576271186441 0.006610169491525424" fullinertia="0.02 0.03 0.04 0.001 0.002 0.003" />
            <site name="ulnar_styloid_left" pos="0.0 0.0 -0.04902542372881356" size="0.02" rgba="1 0 0 1" />
          </body>
        </body>
      </body>
      <body name="right_upper_arm" pos="0 -0.1011906779661017 0.2782506779661017">
        <joint name="right_shoulder_x" type="hinge" axis="1 0 0" pos="0 0.04056 0" range="-180.0 50.0" />
        <joint name="right_shoulder_y" type="hinge" axis="0 1 0" pos="0 0.04056 0" range="-90 90" />
        <joint name="right_shoulder_z" type="hinge" axis="0 0 1" pos="0 0.04056 0" range="-50 180.0" />
        <geom type="capsule" size="0.05563559322033899 0.12476694915254237" pos="0 -0.11202474576271186 0" euler="-90 0 0" rgba="0.2 0.4 0.8 1" />
        <inertial mass="2.4" pos="0.005493050847457628 -0.14709169491525426 -0.009460254237288135" fullinertia="0.02 0.03 0.04 0.001 0.002 0.003" />
        <site name="acromion_right" pos="0.0 0.061033898305084745 0.022254237288135595" size="0.02" rgba="1 0 0 1" />
        <site name="lateral_humeral_epicondyle_right" pos="0.0 -0.3051694915254237 0.05563559322033899" size="0.02" rgba="1 0 0 1" />
        <body name="right_forearm" pos="0 -0.3051694915254237 0">
          <joint name="right_elbow_z" type="hinge" axis="0 0 1" pos="0 0 0" range="0 150.0" />
          <geom type="capsule" size="0.0473728813559322 0.13220338983050844" pos="0 -0.15588983050847455 0" euler="-90 0 0" rgba="0.2 0.4 0.8 1" />
          <inertial mass="1.7000000000000002" pos="-0.0040531355932203385 -0.13001211864406778 0.00342957627118644" fullinertia="0.02 0.03 0.04 0.001 0.002 0.003" />
          <body name="right_hand" pos="0 -0.3117796610169491 0">
            <joint name="right_wrist_y" type="hinge" axis="0 1 0" pos="0 0 0" range="-80 80" />
            <joint name="right_wrist_z" type="hinge" axis="0 0 1" pos="0 0 0" range="-60 60.0" />
            <geom type="capsule" size="0.04902542372881356 0.019555084745762712" pos="0 -0.04406779661016949 0" euler="-90 0 0" rgba="0.2 0.4 0.8 1" />
            <inertial mass="0.6" pos="0.007227118644067796 -0.07394576271186441 0.006610169491525424" fullinertia="0.02 0.03 0.04 0.001 0.002 0.003" />
            <site name="ulnar_styloid_right" pos="0.0 0.0 0.04902542372881356" size="0.02" rgba="1 0 0 1" />
          </body>
        </body>
      </body>
    </body>
  </worldbody>
  <option gravity="0 0 -9.81" />
</mujoco>