<?xml version='1.0' encoding='utf-8'?>
<mujoco model="human">
  <worldbody>
    <geom type="plane" size="1 1 .1" rgba=".8 .8 .8 1" />
    <light diffuse=".8 .8 .8" pos="0 0 3" dir="0 0 -1" />
    <body name="thorax" pos="0 0 1.7090697674418605" euler="90 0 0">
      <joint type="free" pos="0 0 0" />
      <geom type="capsule" size="0.09612209302325583 0.12600000000000003" pos="0 -0.09612209302325583 0" euler="0 0 0" rgba="0.2 0.4 0.8 1" />
      <geom type="capsule" size="0.07864534883720932 0.12600000000000003" pos="0 -0.270889534883721 0" euler="0 0 0" rgba="0.2 0.4 0.8 1" />
      <body name="head" pos="0 0 0">
        <joint name="head_x" type="hinge" axis="1 0 0" pos="0 0 0" range="-45 45" />
        <joint name="head_y" type="hinge" axis="0 1 0" pos="0 0 0" range="-80 80" />
        <joint name="head_z" type="hinge" axis="0 0 1" pos="0 0 0" range="-60 75" />
        <geom type="sphere" size="0.1454651162790698" pos="0 0.1454651162790698 0" euler="0 0 0" rgba="0.2 0.4 0.8 1" />
      </body>
      <body name="abdomen" pos="0 -0.3495348837209303 0">
        <joint name="abdomen_x" type="hinge" axis="1 0 0" pos="0 0 0" range="-12.5 12.5" />
        <joint name="abdomen_y" type="hinge" axis="0 1 0" pos="0 0 0" range="-15 15" />
        <joint name="abdomen_z" type="hinge" axis="0 0 1" pos="0 0 0" range="-25 12.5" />
        <geom type="capsule" size="0.07901162790697674 0.12060000000000001" pos="0 -0.1 0" euler="0 0 0" rgba="0.2 0.4 0.8 1" />
        <body name="pelvis" pos="0 -0.1580232558139535 0">
          <joint name="pelvis_x" type="hinge" axis="1 0 0" pos="0 0 0" range="-12.5 12.5" />
          <joint name="pelvis_y" type="hinge" axis="0 1 0" pos="0 0 0" range="-15 15" />
          <joint name="pelvis_z" type="hinge" axis="0 0 1" pos="0 0 0" range="-25 12.5" />
          <geom type="capsule" size="0.04866279069767442 0.15300000000000002" pos="0 -0.1 0" euler="0 0 0" rgba="0.2 0.4 0.8 1" />
          <body name="left_thigh" pos="0 -0.09732558139534885 -0.126">
            <joint name="left_hip_x" type="hinge" axis="1 0 0" pos="0 0 0" range="-20 40" />
            <joint name="left_hip_y" type="hinge" axis="0 1 0" pos="0 0 0" range="-40 50" />
            <joint name="left_hip_z" type="hinge" axis="0 0 1" pos="0 0 0" range="-30 100" />
            <geom type="capsule" size="0.07200000000000001 0.22604651162790698" pos="0 -0.262046511627907 0" euler="-90 0 0" rgba="0.2 0.4 0.8 1" />
            <body name="left_shank" pos="0 -0.45209302325581396 0">
              <joint name="left_knee_z" type="hinge" axis="0 0 1" pos="0 0 0" range="-150 0" />
              <geom type="capsule" size="0.054 0.22656976744186047" pos="0 -0.22656976744186047 0" euler="-90 0 0" rgba="0.2 0.4 0.8 1" />
              <body name="left_foot" pos="0 -0.45313953488372094 0">
                <joint name="left_ankle_y" type="hinge" axis="0 1 0" pos="0 0 0" range="-30 30" />
                <joint name="left_ankle_z" type="hinge" axis="0 0 1" pos="0 0 0" range="-20 30" />
                <geom type="capsule" size="0.05 0.0727325581395349" pos="0.0727325581395349 0 0" euler="0 90 0" rgba="0.2 0.4 0.8 1" />
              </body>
            </body>
          </body>
          <body name="right_thigh" pos="0 -0.09732558139534885 0.126">
            <joint name="right_hip_x" type="hinge" axis="1 0 0" pos="0 0 0" range="-40 20" />
            <joint name="right_hip_y" type="hinge" axis="0 1 0" pos="0 0 0" range="-40 50" />
            <joint name="right_hip_z" type="hinge" axis="0 0 1" pos="0 0 0" range="-30 100" />
            <geom type="capsule" size="0.07200000000000001 0.22604651162790698" pos="0 -0.262046511627907 0" euler="-90 0 0" rgba="0.2 0.4 0.8 1" />
            <body name="right_shank" pos="0 -0.45209302325581396 0">
              <joint name="right_knee_z" type="hinge" axis="0 0 1" pos="0 0 0" range="-150 0" />
              <geom type="capsule" size="0.054 0.22656976744186047" pos="0 -0.22656976744186047 0" euler="-90 0 0" rgba="0.2 0.4 0.8 1" />
              <body name="right_foot" pos="0 -0.45313953488372094 0">
                <joint name="right_ankle_y" type="hinge" axis="0 1 0" pos="0 0 0" range="-30 30" />
                <joint name="right_ankle_z" type="hinge" axis="0 0 1" pos="0 0 0" range="-20 30" />
                <geom type="capsule" size="0.05 0.0727325581395349" pos="0.0727325581395349 0 0" euler="0 90 0" rgba="0.2 0.4 0.8 1" />
              </body>
            </body>
          </body>
        </body>
      </body>
      <body name="left_upper_arm" pos="0 -0.09612209302325583 -0.25956209302325584">
        <joint name="left_shoulder_x" type="hinge" axis="1 0 0" pos="0 0.03744 0" range="-50 180" />
        <joint name="left_shoulder_y" type="hinge" axis="0 1 0" pos="0 0.03744 0" range="-90 90" />
        <joint name="left_shoulder_z" type="hinge" axis="0 0 1" pos="0 0.03744 0" range="-50 180" />
        <geom type="capsule" size="0.03744 0.1449418604651163" pos="0 -0.10750186046511631 0" euler="-90 0 0" rgba="0.2 0.4 0.8 1" />
        <body name="left_forearm" pos="0 -0.2898837209302326 0">
          <joint name="left_elbow_z" type="hinge" axis="0 0 1" pos="0 0 0" range="0 150" />
          <geom type="capsule" size="0.035 0.1480813953488372" pos="0 -0.1480813953488372 0" euler="-90 0 0" rgba="0.2 0.4 0.8 1" />
          <body name="left_hand" pos="0 -0.2961627906976744 0">
            <joint name="left_wrist_y" type="hinge" axis="0 1 0" pos="0 0 0" range="-80 80" />
            <joint name="left_wrist_z" type="hinge" axis="0 0 1" pos="0 0 0" range="-60 60" />
            <geom type="capsule" size="0.045 0.041860465116279076" pos="0 -0.041860465116279076 0" euler="-90 0 0" rgba="0.2 0.4 0.8 1" />
          </body>
        </body>
      </body>
      <body name="right_upper_arm" pos="0 -0.09612209302325583 0.25956209302325584">
        <joint name="right_shoulder_x" type="hinge" axis="1 0 0" pos="0 0.03744 0" range="-50 180" />
        <joint name="right_shoulder_y" type="hinge" axis="0 1 0" pos="0 0.03744 0" range="-90 90" />
        <joint name="right_shoulder_z" type="hinge" axis="0 0 1" pos="0 0.03744 0" range="-50 180" />
        <geom type="capsule" size="0.03744 0.1449418604651163" pos="0 -0.10750186046511631 0" euler="-90 0 0" rgba="0.2 0.4 0.8 1" />
        <body name="right_forearm" pos="0 -0.2898837209302326 0">
          <joint name="right_elbow_z" type="hinge" axis="0 0 1" pos="0 0 0" range="0 150" />
          <geom type="capsule" size="0.035 0.1480813953488372" pos="0 -0.1480813953488372 0" euler="-90 0 0" rgba="0.2 0.4 0.8 1" />
          <body name="right_hand" pos="0 -0.2961627906976744 0">
            <joint name="right_wrist_y" type="hinge" axis="0 1 0" pos="0 0 0" range="-80 80" />
            <joint name="right_wrist_z" type="hinge" axis="0 0 1" pos="0 0 0" range="-60 60" />
            <geom type="capsule" size="0.045 0.041860465116279076" pos="0 -0.041860465116279076 0" euler="-90 0 0" rgba="0.2 0.4 0.8 1" />
          </body>
        </body>
      </body>
    </body>
  </worldbody>
  <option gravity="0 0 -9.81" />
</mujoco>