<?xml version='1.0' encoding='utf-8'?>
<mujoco model="simple_human">
  <worldbody>
    <geom type="plane" size="1 1 .1" rgba=".8 .8 .8 1" />
    <light diffuse=".8 .8 .8" pos="0 0 3" dir="0 0 -1" />
    <body name="thorax" pos="0 0 1.5">
      <joint type="free" pos="0 0 0" />
      <geom type="capsule" size="0.1 0.334" euler="90 0 0" rgba="0.8 0.6 0.2 1" />
      <body name="head" pos="0 0 0.6120000000000001">
        <joint name="head_x" type="hinge" axis="1 0 0" pos="0 0 -0.278" />
        <joint name="head_y" type="hinge" axis="0 1 0" pos="0 0 -0.278" />
        <joint name="head_z" type="hinge" axis="0 0 1" pos="0 0 -0.278" />
        <geom type="sphere" size="0.278" euler="90 0 0" rgba="0.8 0.6 0.2 1" />
      </body>
      <body name="abdomen" pos="0 0 -0.485">
        <joint name="abdomen_x" type="hinge" axis="1 0 0" pos="0 0 0" />
        <joint name="abdomen_y" type="hinge" axis="0 1 0" pos="0 0 0" />
        <joint name="abdomen_z" type="hinge" axis="0 0 1" pos="0 0 0" />
        <geom type="capsule" size="0.1 0.151" euler="90 0 0" rgba="0.8 0.6 0.2 1" />
        <body name="pelvis" pos="0 0 -0.244">
          <joint name="pelvis_x" type="hinge" axis="1 0 0" pos="0 0 0" />
          <joint name="pelvis_y" type="hinge" axis="0 1 0" pos="0 0 0" />
          <joint name="pelvis_z" type="hinge" axis="0 0 1" pos="0 0 0" />
          <geom type="capsule" size="0.1 0.093" euler="90 0 0" rgba="0.8 0.6 0.2 1" />
          <body name="left_thigh" pos="0 0.186 -0.525">
            <joint name="left_hip_x" type="hinge" axis="1 0 0" pos="0 0 0.432" />
            <joint name="left_hip_y" type="hinge" axis="0 1 0" pos="0 0 0.432" />
            <joint name="left_hip_z" type="hinge" axis="0 0 1" pos="0 0 0.432" />
            <geom type="capsule" size="0.04 0.432" euler="0 0 0" rgba="0.8 0.6 0.2 1" />
            <body name="left_shank" pos="0 0 -0.865">
              <joint name="left_knee_y" type="hinge" axis="0 1 0" pos="0 0 0.433" />
              <geom type="capsule" size="0.035 0.433" euler="0 0 0" rgba="0.8 0.6 0.2 1" />
              <body name="left_foot" pos="0.139 0 -0.5720000000000001">
                <joint name="left_ankle_y" type="hinge" axis="0 1 0" pos="0 0 0.139" />
                <joint name="left_ankle_z" type="hinge" axis="0 0 1" pos="0 0 0.139" />
                <geom type="capsule" size="0.05 0.139" euler="90 90 0" rgba="0.8 0.6 0.2 1" />
              </body>
            </body>
          </body>
          <body name="right_thigh" pos="0 -0.186 -0.525">
            <joint name="right_hip_x" type="hinge" axis="1 0 0" pos="0 0 0.432" />
            <joint name="right_hip_y" type="hinge" axis="0 1 0" pos="0 0 0.432" />
            <joint name="right_hip_z" type="hinge" axis="0 0 1" pos="0 0 0.432" />
            <geom type="capsule" size="0.04 0.432" euler="0 0 0" rgba="0.8 0.6 0.2 1" />
            <body name="right_shank" pos="0 0 -0.865">
              <joint name="right_knee_y" type="hinge" axis="0 1 0" pos="0 0 0.433" />
              <geom type="capsule" size="0.035 0.433" euler="0 0 0" rgba="0.8 0.6 0.2 1" />
              <body name="right_foot" pos="0.139 0 -0.5720000000000001">
                <joint name="right_ankle_y" type="hinge" axis="0 1 0" pos="0 0 0.139" />
                <joint name="right_ankle_z" type="hinge" axis="0 0 1" pos="0 0 0.139" />
                <geom type="capsule" size="0.05 0.139" euler="90 90 0" rgba="0.8 0.6 0.2 1" />
              </body>
            </body>
          </body>
        </body>
      </body>
    </body>
  </worldbody>
  <option gravity="0 0 -9.81" />
</mujoco>