<!-- This is a MuJoCo xml file  -->
<mujoco model="floating_base">

    <visual>
        <global azimuth="180" elevation="-20"/>
        <headlight ambient="0.3 0.3 0.3" diffuse="0.6 0.6 0.6" specular="0 0 0"/>
    </visual>

    <worldbody>
        <light pos="0 0 1"/>
        <geom type="plane" size="5 5 0.1" rgba="0.9 0.9 0.9 0.3"/>
        <body name="base" pos="0 0 2">
            <joint name="free" type="free"/>
            <geom type="box" size="0.05 0.05 0.05" rgba="1 1 1 1"/>
            <body name="link1" pos="0 0 0.05">
                <inertial pos="0 0 0.5" mass="4" fullinertia="1 1 1 0 0 0"/>
                <geom type="box" size="0.05 0.05 0.5" pos="0 0 0.5" euler="0 0 0"/>
                <joint name="joint1" type="hinge" axis="0 -1 0"/>
                <site name="tip1" size="0.1" pos="0 0 1" rgba="1 0 0 1"/>    
                <body name="link2" pos="0 0 1">
                    <geom type="box" size="0.05 0.05 0.5" pos="0 0 0.5" rgba="0 0 1 1"/>
                    <joint name="joint2" type="hinge" axis="0 -1 0"/>
                </body>
            </body>
        </body>
    </worldbody>

</mujoco>